Workbook

Sheet IURAN TANAH
A1: No | B1: Nama | C1: Perum | D1: Blok | E1: No HP | F1: SALDO 2024 | G1: SALDO 2025 | H1: JANUARI | I1: FEBRUARI | J1: MARET | K1: APRIL | L1: MEI | M1: JUNI | N1: JULI | O1: AGUSTUS | P1: SEPTEMBER | Q1: OKTOBER | R1: NOVEMBER | S1: DESEMBER | T1: Total
A2: A0001 | B2: SURYO WINOTO | C2: BRI | D2: A-00 | E2: 085278032476 | F2: 300000 | G2: =F2+SUM(H2:S2) -> 300000 | T2: =G2 -> 300000
A3: A0002 | B3: RIO | C3: BRI | D3: A-02 | F3: 500000 | G3: =F3+SUM(H3:S3) -> 500000 | T3: =G3 -> 500000
A4: A0003 | B4: ALEX | C4: BRI | D4: A-03 | E4: 081225141604 | F4: 275000 | G4: =F4+SUM(H4:S4) -> 275000 | T4: =G4 -> 275000
A5: A0004 | B5: NANANG | C5: BRI | D5: A-06 | F5: 100000 | G5: =F5+SUM(H5:S5) -> 100000 | T5: =G5 -> 100000
A6: A0005 | B6: AZIZ | C6: BRI | D6: A-07 | E6: 085272036042 | F6: 350000 | G6: =F6+SUM(H6:S6) -> 450000 | H6: 50000 | I6: 50000 | T6: =G6 -> 450000
A7: A0006 | B7: MARVIN | C7: BRI | D7: A-09 | E7: 082389129277 | F7: 150000 | G7: =F7+SUM(H7:S7) -> 250000 | H7: 50000 | I7: 50000 | T7: =G7 -> 250000
A8: A0007 | B8: PUTRA | C8: BRI | D8: A-14 | E8: 081277134843 | F8: 40000 | G8: =F8+SUM(H8:S8) -> 40000 | T8: =G8 -> 40000
A9: A0008 | B9: ZULFAJRI | C9: BRI | D9: A-16 | E9: 082170182359 | F9: 25000 | G9: =F9+SUM(H9:S9) -> 25000 | T9: =G9 -> 25000
A10: A0009 | B10: SYAFRUDDIN | C10: BRI | D10: A-18 | F10: 200000 | G10: =F10+SUM(H10:S10) -> 350000 | H10: 50000 | I10: 50000 | L10: 50000 | T10: =G10 -> 350000
A11: A0010 | B11: DAVI | C11: BRI | D11: A-19 | F11: 100000 | G11: =F11+SUM(H11:S11) -> 200000 | H11: 50000 | I11: 50000 | T11: =G11 -> 200000
A12: A0012 | B12: AHMAT | C12: BRI | D12: A-21 | E12: 081383748814 | F12: 100000 | G12: =F12+SUM(H12:S12) -> 100000 | T12: =G12 -> 100000
A13: A0013 | B13: DEFRIZAL | C13: BRI | D13: A-23 | E13: 081388685011 | F13: 500000 | G13: =F13+SUM(H13:S13) -> 650000 | H13: 50000 | I13: 50000 | L13: 50000 | T13: =G13 -> 650000
A14: A0014 | B14: ADEK | C14: BRI | D14: A-24 | E14: 082283513560 | F14: 250000 | G14: =F14+SUM(H14:S14) -> 250000 | T14: =G14 -> 250000
A15: A0015 | B15: BUSMAN | C15: BRI | D15: B-01 | F15: 500000 | G15: =F15+SUM(H15:S15) -> 500000 | T15: =G15 -> 500000
A16: A0016 | B16: OYON | C16: BRI | D16: B-02 | F16: 200000 | G16: =F16+SUM(H16:S16) -> 200000 | T16: =G16 -> 200000
A17: A0017 | B17: RINALDI | C17: BRI | D17: B-03 | F17: 50000 | G17: =F17+SUM(H17:S17) -> 50000 | T17: =G17 -> 50000
A18: A0018 | B18: ANTONI | C18: BRI | D18: B-04 | F18: 1500000 | G18: =F18+SUM(H18:S18) -> 1500000 | T18: =G18 -> 1500000
A19: A0019 | B19: ABD MUHAFIZ NASUTION | C19: BRI | D19: B-05 | E19: 081270071124 | F19: 300000 | G19: =F19+SUM(H19:S19) -> 300000 | T19: =G19 -> 300000
A20: A0020 | B20: MAISYARAH | C20: BRI | D20: B-06 | E20: 081261542824 | F20: 10000 | G20: =F20+SUM(H20:S20) -> 10000 | T20: =G20 -> 10000
A21: A0021 | B21: WILI | C21: BRI | D21: B-08 | E21: 082358845454 | F21: 150000 | G21: =F21+SUM(H21:S21) -> 150000 | T21: =G21 -> 150000
A22: A0022 | B22: HENDRA | C22: BRI | D22: B-09 | E22: 081378207690 | F22: 200000 | G22: =F22+SUM(H22:S22) -> 200000 | T22: =G22 -> 200000
A23: A0023 | B23: AZWIR | C23: BRI | D23: B-10 | E23: 081364881722 | F23: 250000 | G23: =F23+SUM(H23:S23) -> 300000 | H23: 50000 | T23: =G23 -> 300000
A24: A0024 | B24: ACIN | C24: BRI | D24: B-11 | E24: 081269541212 | F24: 200000 | G24: =F24+SUM(H24:S24) -> 200000 | T24: =G24 -> 200000
A25: A0025 | B25: NAZRI | C25: BRI | D25: B-12 | E25: 082286622199 | F25: 200000 | G25: =F25+SUM(H25:S25) -> 250000 | H25: 50000 | T25: =G25 -> 250000
A26: A0026 | B26: DANI | C26: BRI | D26: B-14 | E26: 08526328333 | F26: 150000 | G26: =F26+SUM(H26:S26) -> 250000 | H26: 50000 | J26: 50000 | T26: =G26 -> 250000
A27: A0027 | B27: INDRA /WAHIDAR | C27: BRI | E27: 082272464633 | F27: 150000 | G27: =F27+SUM(H27:S27) -> 150000 | T27: =G27 -> 150000
A28: A0028 | B28: AMRIL HAMBIYA | C28: ERCE | D28: A-01 | F28: 500000 | G28: =F28+SUM(H28:S28) -> 500000 | T28: =G28 -> 500000
A29: A0029 | B29: SELLY | C29: ERCE | D29: A-02 | F29: 150000 | G29: =F29+SUM(H29:S29) -> 250000 | H29: 50000 | I29: 50000 | T29: =G29 -> 250000
A30: A0030 | B30: ASRIZAL | C30: ERCE | D30: A-03 | E30: 081372731426 | F30: 50000 | G30: =F30+SUM(H30:S30) -> 50000 | T30: =G30 -> 50000
A31: A0031 | B31: PEMBERLIAN TONI | C31: ERCE | D31: A-04 | F31: 200000 | G31: =F31+SUM(H31:S31) -> 200000 | T31: =G31 -> 200000
A32: A0032 | B32: YUSPIONO | C32: ERCE | D32: A-05 | F32: 350000 | G32: =F32+SUM(H32:S32) -> 350000 | T32: =G32 -> 350000
A33: A0033 | B33: RISDA / TORANG S | C33: ERCE | D33: A-06 | F33: 50000 | G33: =F33+SUM(H33:S33) -> 50000 | T33: =G33 -> 50000
A34: A0034 | B34: HELDAWATI | C34: ERCE | D34: B-01 | E34: 082390914999 | F34: 200000 | G34: =F34+SUM(H34:S34) -> 300000 | H34: 50000 | I34: 50000 | T34: =G34 -> 300000
A35: A0035 | B35: JOKO | C35: ERCE | D35: B-02 | E35: 082384966600 | F35: 250000 | G35: =F35+SUM(H35:S35) -> 350000 | H35: 50000 | I35: 50000 | T35: =G35 -> 350000
A36: A0036 | B36: RUDI | C36: ERCE | D36: B-03 | F36: 1000000 | G36: =F36+SUM(H36:S36) -> 1000000 | T36: =G36 -> 1000000
A37: A0037 | B37: SILABAN | C37: ERCE | D37: B-05 | E37: 082387631737 | F37: 0 | G37: =F37+SUM(H37:S37) -> 0 | T37: =G37 -> 0
A38: A0038 | B38: EKO | C38: ERCE | D38: B-06 | E38: 081914438999 | F38: 100000 | G38: =F38+SUM(H38:S38) -> 100000 | T38: =G38 -> 100000
A39: A0039 | B39: AHMAD | C39: ERCE | D39: B-07 | E39: 081276709499 | F39: 400000 | G39: =F39+SUM(H39:S39) -> 400000 | T39: =G39 -> 400000
A40: A0040 | B40: ALFIZ | C40: ERCE | D40: B-08 | E40: 08238879821 | F40: 100000 | G40: =F40+SUM(H40:S40) -> 100000 | T40: =G40 -> 100000
...

Sheet IURAN BULANAN
A2: No | B2: Nama | C2: Perum | D2: Blok | E2: No HP | F2: JANUARI | G2: FEBRUARI | H2: MARET | I2: APRIL | J2: MEI | K2: JUNI | L2: JULI | M2: AGUSTUS | N2: SEPTEMBER | O2: OKTOBER | P2: NOVEMBER | Q2: DESEMBER | R2: Total
A3: A0001 | B3: SURYO WINOTO | C3: BRI | D3: A-00 | E3: 085278032476 | R3: =SUM(F3:Q3) -> 0
A4: A0002 | B4: RIO | C4: BRI | D4: A-02 | F4: 10000 | G4: 10000 | R4: =SUM(F4:Q4) -> 20000
A5: A0003 | B5: ALEX | C5: BRI | D5: A-03 | E5: 081225141604 | F5: 10000 | R5: =SUM(F5:Q5) -> 10000
A6: A0004 | B6: NANANG | C6: BRI | D6: A-06 | R6: =SUM(F6:Q6) -> 0
A7: A0005 | B7: AZIZ | C7: BRI | D7: A-07 | E7: 085272036042 | F7: 10000 | G7: 10000 | R7: =SUM(F7:Q7) -> 20000
A8: A0006 | B8: MARVIN | C8: BRI | D8: A-09 | E8: 082389129277 | F8: 10000 | G8: 10000 | H8: 10000 | I8: 10000 | R8: =SUM(F8:Q8) -> 40000
A9: A0007 | B9: PUTRA | C9: BRI | D9: A-14 | E9: 081277134843 | R9: =SUM(F9:Q9) -> 0
A10: A0008 | B10: ZULFAJRI | C10: BRI | D10: A-16 | E10: 082170182359 | R10: =SUM(F10:Q10) -> 0
A11: A0009 | B11: SYAFRUDDIN | C11: BRI | D11: A-18 | F11: 10000 | G11: 10000 | H11: 10000 | I11: 10000 | J11: 10000 | R11: =SUM(F11:Q11) -> 50000
A12: A0010 | B12: DAVI | C12: BRI | D12: A-19 | F12: 10000 | G12: 10000 | R12: =SUM(F12:Q12) -> 20000
A13: A0012 | B13: AHMAT | C13: BRI | D13: A-21 | E13: 081383748814 | F13: 10000 | G13: 10000 | R13: =SUM(F13:Q13) -> 20000
A14: A0013 | B14: DEFRIZAL | C14: BRI | D14: A-23 | E14: 081388685011 | F14: 10000 | G14: 10000 | R14: =SUM(F14:Q14) -> 20000
A15: A0014 | B15: ADEK | C15: BRI | D15: A-24 | E15: 082283513560 | F15: 10000 | G15: 10000 | I15: 10000 | J15: 10000 | R15: =SUM(F15:Q15) -> 40000
A16: A0015 | B16: BUSMAN | C16: BRI | D16: B-01 | F16: 10000 | G16: 10000 | R16: =SUM(F16:Q16) -> 20000
A17: A0016 | B17: OYON | C17: BRI | D17: B-02 | F17: 10000 | G17: 10000 | R17: =SUM(F17:Q17) -> 20000
A18: A0017 | B18: RINALDI | C18: BRI | D18: B-03 | R18: =SUM(F18:Q18) -> 0
A19: A0018 | B19: ANTONI | C19: BRI | D19: B-04 | R19: =SUM(F19:Q19) -> 0
A20: A0019 | B20: ABD MUHAFIZ NASUTION | C20: BRI | D20: B-05 | E20: 081270071124 | F20: 10000 | G20: 10000 | R20: =SUM(F20:Q20) -> 20000
A21: A0020 | B21: MAISYARAH | C21: BRI | D21: B-06 | E21: 081261542824 | R21: =SUM(F21:Q21) -> 0
A22: A0021 | B22: WILI | C22: BRI | D22: B-08 | E22: 082358845454 | F22: 10000 | G22: 10000 | R22: =SUM(F22:Q22) -> 20000
A23: A0022 | B23: HENDRA | C23: BRI | D23: B-09 | E23: 081378207690 | F23: 10000 | G23: 10000 | H23: 10000 | I23: 10000 | J23: 10000 | K23: 10000 | L23: 10000 | R23: =SUM(F23:Q23) -> 70000
A24: A0023 | B24: AZWIR | C24: BRI | D24: B-10 | E24: 081364881722 | F24: 10000 | G24: 10000 | H24: 10000 | I24: 10000 | J24: 10000 | R24: =SUM(F24:Q24) -> 50000
A25: A0024 | B25: ACIN | C25: BRI | D25: B-11 | E25: 081269541212 | F25: 10000 | G25: 10000 | I25: 10000 | J25: 10000 | R25: =SUM(F25:Q25) -> 40000
A26: A0025 | B26: NAZRI | C26: BRI | D26: B-12 | E26: 082286622199 | F26: 10000 | G26: 10000 | R26: =SUM(F26:Q26) -> 20000
A27: A0026 | B27: DANI | C27: BRI | D27: B-14 | E27: 08526328333 | F27: 10000 | G27: 10000 | H27: 10000 | I27: 10000 | J27: 10000 | R27: =SUM(F27:Q27) -> 50000
A28: A0027 | B28: INDRA /WAHIDAR | C28: BRI | E28: 082272464633 | F28: 10000 | G28: 10000 | R28: =SUM(F28:Q28) -> 20000
A29: A0028 | B29: AMRIL HAMBIYA | C29: ERCE | D29: A-01 | F29: 10000 | R29: =SUM(F29:Q29) -> 10000
A30: A0029 | B30: SELLY | C30: ERCE | D30: A-02 | F30: 10000 | G30: 10000 | R30: =SUM(F30:Q30) -> 20000
A31: A0030 | B31: ASRIZAL | C31: ERCE | D31: A-03 | E31: 081372731426 | R31: =SUM(F31:Q31) -> 0
A32: A0031 | B32: PEMBERLIAN TONI | C32: ERCE | D32: A-04 | R32: =SUM(F32:Q32) -> 0
A33: A0032 | B33: YUSPIONO | C33: ERCE | D33: A-05 | F33: 10000 | G33: 10000 | R33: =SUM(F33:Q33) -> 20000
A34: A0033 | B34: RISDA / TORANG S | C34: ERCE | D34: A-06 | R34: =SUM(F34:Q34) -> 0
A35: A0034 | B35: HELDAWATI | C35: ERCE | D35: B-01 | E35: 082390914999 | F35: 10000 | G35: 10000 | R35: =SUM(F35:Q35) -> 20000
A36: A0035 | B36: JOKO | C36: ERCE | D36: B-02 | E36: 082384966600 | F36: 10000 | G36: 10000 | R36: =SUM(F36:Q36) -> 20000
A37: A0036 | B37: RUDI | C37: ERCE | D37: B-03 | F37: 10000 | G37: 10000 | R37: =SUM(F37:Q37) -> 20000
A38: A0037 | B38: SILABAN | C38: ERCE | D38: B-05 | E38: 082387631737 | F38: 10000 | G38: 10000 | R38: =SUM(F38:Q38) -> 20000
A39: A0038 | B39: EKO | C39: ERCE | D39: B-06 | E39: 081914438999 | F39: 10000 | G39: 10000 | R39: =SUM(F39:Q39) -> 20000
A40: A0039 | B40: AHMAD | C40: ERCE | D40: B-07 | E40: 081276709499 | R40: =SUM(F40:Q40) -> 0
A41: A0040 | B41: ALFIZ | C41: ERCE | D41: B-08 | E41: 08238879821 | R41: =SUM(F41:Q41) -> 0
...

Sheet SALDO IURAN TANAH
B1: Pemakaian Uang Iuran Tanah
B3: Tgl | C3: Keterangan | D3: Debet | E3: Credit | F3: Saldo
C4: Saldo Iuran Tanah 31 Desember 2024 | F4: 18757000
B5: 45771 | C5: Iuran Tanah GGL ( JAN-FEB 2025 ) | E5: 200000 | F5: =F4-Table2[[#This Row],[Debet]]+Table2[[#This Row],[Credit]] -> 18957000
B6: 45771 | C6: Iuran Tanah RCM-BRI-Sekitar | E6: 1500000 | F6: =F5-Table2[[#This Row],[Debet]]+Table2[[#This Row],[Credit]] -> 20457000
F7: =F6-Table2[[#This Row],[Debet]]+Table2[[#This Row],[Credit]] -> 20457000
F8: =F7-Table2[[#This Row],[Debet]]+Table2[[#This Row],[Credit]] -> 20457000
F9: =F8-Table2[[#This Row],[Debet]]+Table2[[#This Row],[Credit]] -> 20457000
F10: =F9-Table2[[#This Row],[Debet]]+Table2[[#This Row],[Credit]] -> 20457000
F11: =F10-Table2[[#This Row],[Debet]]+Table2[[#This Row],[Credit]] -> 20457000
F12: =F11-Table2[[#This Row],[Debet]]+Table2[[#This Row],[Credit]] -> 20457000
F13: =F12-Table2[[#This Row],[Debet]]+Table2[[#This Row],[Credit]] -> 20457000
F14: =F13-Table2[[#This Row],[Debet]]+Table2[[#This Row],[Credit]] -> 20457000
F15: =F14-Table2[[#This Row],[Debet]]+Table2[[#This Row],[Credit]] -> 20457000
F16: =F15-Table2[[#This Row],[Debet]]+Table2[[#This Row],[Credit]] -> 20457000
F17: =F16-Table2[[#This Row],[Debet]]+Table2[[#This Row],[Credit]] -> 20457000
F18: =F17-Table2[[#This Row],[Debet]]+Table2[[#This Row],[Credit]] -> 20457000
... F29: =F28-Table2[[#This Row],[Debet]]+Table2[[#This Row],[Credit]] -> 20457000
D33: Diketahui
B34: Bendahara | D34: Sekretaris | F34: Ketua
B38: (Novpiar Effendi) | D38: (Rohman) | F38: (Yuspiono)

Sheet SALDO IURAN 2025
B1: Saldo Iuran Bulanan 2024
B3: Tgl | C3: Keterangan | D3: Debet | E3: Credit | F3: Saldo
C4: Saldo Iuran bulanantahun 2024 | F4: 2794000
B5: 45771 | C5: Iuran Bln JAN-Maret 2025 GGL | E5: 1360000 | F5: =F4-Table22[[#This Row],[Debet]]+Table22[[#This Row],[Credit]] -> 4154000
B6: 45771 | C6: Fardu kifayah anak dari Doni ggl e-16 | D6: 600000 | F6: =F5-Table22[[#This Row],[Debet]]+Table22[[#This Row],[Credit]] -> 3554000
B7: 45771 | C7: Fardu kifayah mertua Riko ggl B-13 | D7: 1800000 | F7: =F6-Table22[[#This Row],[Debet]]+Table22[[#This Row],[Credit]] -> 1754000
B8: 45771 | C8: Iuran bln jan-juni RTM | E8: 170000 | F8: =F7-Table22[[#This Row],[Debet]]+Table22[[#This Row],[Credit]] -> 1924000
B9: 45771 | C9: Iuran BRI-RCM Jan-feb (bbrp s.d juli) | E9: 900000 | F9: =F8-Table22[[#This Row],[Debet]]+Table22[[#This Row],[Credit]] -> 2824000
F10: =F9-Table22[[#This Row],[Debet]]+Table22[[#This Row],[Credit]] -> 2824000
F11: =F10-Table22[[#This Row],[Debet]]+Table22[[#This Row],[Credit]] -> 2824000
F12: =F11-Table22[[#This Row],[Debet]]+Table22[[#This Row],[Credit]] -> 2824000
F13: =F12-Table22[[#This Row],[Debet]]+Table22[[#This Row],[Credit]] -> 2824000
F14: =F13-Table22[[#This Row],[Debet]]+Table22[[#This Row],[Credit]] -> 2824000
F15: =F14-Table22[[#This Row],[Debet]]+Table22[[#This Row],[Credit]] -> 2824000
F16: =F15-Table22[[#This Row],[Debet]]+Table22[[#This Row],[Credit]] -> 2824000
F17: =F16-Table22[[#This Row],[Debet]]+Table22[[#This Row],[Credit]] -> 2824000
F18: =F17-Table22[[#This Row],[Debet]]+Table22[[#This Row],[Credit]] -> 2824000
F19: =F18-Table22[[#This Row],[Debet]]+Table22[[#This Row],[Credit]] -> 2824000
F20: =F19-Table22[[#This Row],[Debet]]+Table22[[#This Row],[Credit]] -> 2824000
F21: =F20-Table22[[#This Row],[Debet]]+Table22[[#This Row],[Credit]] -> 2824000
F22: =F21-Table22[[#This Row],[Debet]]+Table22[[#This Row],[Credit]] -> 2824000
B25: Dibuat .12 Januari 2025 | D25: Diketahui
B26: Bendahara | D26: Sekretaris | F26: Ketua
B30: (Novpiar Effendi) | D30: (Rohman) | F30: (Yuspiono)

Sheet KARTU IURANTANAH
B1: IURAN TANAH MAKAM BSKM RT 007/001 DUSUN I - TARAI BANGUN
B3: No | C3: : | D3: 1 | F3: No | G3: : | H3: 2 | J3: No | K3: : | L3: 3
B4: Nama | C4: : | D4: =VLOOKUP(D3,'IURAN TANAH'!$A$2:$S$145,2,FALSE) -> #N/A | F4: Nama | G4: : | H4: =VLOOKUP(H3,'IURAN TANAH'!$A$2:$S$145,2,FALSE) -> #N/A | J4: Nama | K4: : | L4: =VLOOKUP(L3,'IURAN TANAH'!$A$2:$S$145,2,FALSE) -> #N/A
B5: Alamat | C5: : | D5: =VLOOKUP(D3,'IURAN TANAH'!$A$2:$S$145,3,FALSE) &" " &VLOOKUP(D3,'IURAN TANAH'!$A$2:$S$145,4,FALSE) -> #N/A | F5: Alamat | G5: : | H5: =VLOOKUP(H3,'IURAN TANAH'!$A$2:$S$145,3,FALSE) &" " &VLOOKUP(H3,'IURAN TANAH'!$A$2:$S$145,4,FALSE) -> #N/A | J5: Alamat | K5: : | L5: =VLOOKUP(L3,'IURAN TANAH'!$A$2:$S$145,3,FALSE) &" " &VLOOKUP(L3,'IURAN TANAH'!$A$2:$S$145,4,FALSE) -> #N/A
B7: IURAN : | F7: IURAN : | J7: IURAN :
B8: Ang 1 | D8: =VLOOKUP(D3,'IURAN TANAH'!$A$2:$S$145,7,FALSE) -> #N/A | F8: Ang 1 | H8: =VLOOKUP(H3,'IURAN TANAH'!$A$2:$S$145,7,FALSE) -> #N/A | J8: Ang 1 | L8: =VLOOKUP(L3,'IURAN TANAH'!$A$2:$S$145,7,FALSE) -> #N/A
B9: Ang 2 | D9: =VLOOKUP(D3,'IURAN TANAH'!$A$2:$S$145,8,FALSE) -> #N/A | F9: Ang 2 | H9: =VLOOKUP(H3,'IURAN TANAH'!$A$2:$S$145,8,FALSE) -> #N/A | J9: Ang 2 | L9: =VLOOKUP(L3,'IURAN TANAH'!$A$2:$S$145,8,FALSE) -> #N/A
B10: Ang 3 | D10: =VLOOKUP(D3,'IURAN TANAH'!$A$2:$S$145,9,FALSE) -> #N/A | F10: Ang 3 | H10: =VLOOKUP(H3,'IURAN TANAH'!$A$2:$S$145,9,FALSE) -> #N/A | J10: Ang 3 | L10: =VLOOKUP(L3,'IURAN TANAH'!$A$2:$S$145,9,FALSE) -> #N/A
B11: Ang 4 | D11: =VLOOKUP(D3,'IURAN TANAH'!$A$2:$S$145,10,FALSE) -> #N/A | F11: Ang 4 | H11: =VLOOKUP(H3,'IURAN TANAH'!$A$2:$S$145,10,FALSE) -> #N/A | J11: Ang 4 | L11: =VLOOKUP(L3,'IURAN TANAH'!$A$2:$S$145,10,FALSE) -> #N/A
B12: Ang 5 | D12: =VLOOKUP(D3,'IURAN TANAH'!$A$2:$S$145,11,FALSE) -> #N/A | F12: Ang 5 | H12: =VLOOKUP(H3,'IURAN TANAH'!$A$2:$S$145,11,FALSE) -> #N/A | J12: Ang 5 | L12: =VLOOKUP(L3,'IURAN TANAH'!$A$2:$S$145,11,FALSE) -> #N/A
B13: Ang 6 | D13: =VLOOKUP(D3,'IURAN TANAH'!$A$2:$S$145,12,FALSE) -> #N/A | F13: Ang 6 | H13: =VLOOKUP(H3,'IURAN TANAH'!$A$2:$S$145,12,FALSE) -> #N/A | J13: Ang 6 | L13: =VLOOKUP(L3,'IURAN TANAH'!$A$2:$S$145,12,FALSE) -> #N/A
B14: Ang 7 | D14: =VLOOKUP(D3,'IURAN TANAH'!$A$2:$S$145,13,FALSE) -> #N/A | F14: Ang 7 | H14: =VLOOKUP(H3,'IURAN TANAH'!$A$2:$S$145,13,FALSE) -> #N/A | J14: Ang 7 | L14: =VLOOKUP(L3,'IURAN TANAH'!$A$2:$S$145,13,FALSE) -> #N/A
B15: Ang 8 | D15: =VLOOKUP(D3,'IURAN TANAH'!$A$2:$S$145,14,FALSE) -> #N/A | F15: Ang 8 | H15: =VLOOKUP(H3,'IURAN TANAH'!$A$2:$S$145,14,FALSE) -> #N/A | J15: Ang 8 | L15: =VLOOKUP(L3,'IURAN TANAH'!$A$2:$S$145,14,FALSE) -> #N/A
B16: Ang 9 | D16: =VLOOKUP(D3,'IURAN TANAH'!$A$2:$S$145,15,FALSE) -> #N/A | F16: Ang 9 | H16: =VLOOKUP(H3,'IURAN TANAH'!$A$2:$S$145,15,FALSE) -> #N/A | J16: Ang 9 | L16: =VLOOKUP(L3,'IURAN TANAH'!$A$2:$S$145,15,FALSE) -> #N/A
B17: Ang 10 | D17: =VLOOKUP(D3,'IURAN TANAH'!$A$2:$S$145,16,FALSE) -> #N/A | F17: Ang 10 | H17: =VLOOKUP(H3,'IURAN TANAH'!$A$2:$S$145,16,FALSE) -> #N/A | J17: Ang 10 | L17: =VLOOKUP(L3,'IURAN TANAH'!$A$2:$S$145,16,FALSE) -> #N/A
B18: Total | D18: =SUM(D8:D17) -> #N/A | F18: Total | H18: =SUM(H8:H17) -> #N/A | J18: Total | L18: =SUM(L8:L17) -> #N/A
B21: No | C21: : | D21: 4 | F21: No | G21: : | H21: 5 | J21: No | K21: : | L21: 6
B22: Nama | C22: : | D22: =VLOOKUP(D21,'IURAN TANAH'!$A$2:$S$145,2,FALSE) -> #N/A | F22: Nama | G22: : | H22: =VLOOKUP(H21,'IURAN TANAH'!$A$2:$S$145,2,FALSE) -> #N/A | J22: Nama | K22: : | L22: =VLOOKUP(L21,'IURAN TANAH'!$A$2:$S$145,2,FALSE) -> #N/A
B23: Alamat | C23: : | D23: =VLOOKUP(D21,'IURAN TANAH'!$A$2:$S$145,3,FALSE) &" " &VLOOKUP(D21,'IURAN TANAH'!$A$2:$S$145,4,FALSE) -> #N/A | F23: Alamat | G23: : | H23: =VLOOKUP(H21,'IURAN TANAH'!$A$2:$S$145,3,FALSE) &" " &VLOOKUP(H21,'IURAN TANAH'!$A$2:$S$145,4,FALSE) -> #N/A | J23: Alamat | K23: : | L23: =VLOOKUP(L21,'IURAN TANAH'!$A$2:$S$145,3,FALSE) &" " &VLOOKUP(L21,'IURAN TANAH'!$A$2:$S$145,4,FALSE) -> #N/A
B25: IURAN : | F25: IURAN : | J25: IURAN :
B26: Ang 1 | D26: =VLOOKUP(D21,'IURAN TANAH'!$A$2:$S$145,7,FALSE) -> #N/A | F26: Ang 1 | H26: =VLOOKUP(H21,'IURAN TANAH'!$A$2:$S$145,7,FALSE) -> #N/A | J26: Ang 1 | L26: =VLOOKUP(L21,'IURAN TANAH'!$A$2:$S$145,7,FALSE) -> #N/A
B27: Ang 2 | D27: =VLOOKUP(D21,'IURAN TANAH'!$A$2:$S$145,8,FALSE) -> #N/A | F27: Ang 2 | H27: =VLOOKUP(H21,'IURAN TANAH'!$A$2:$S$145,8,FALSE) -> #N/A | J27: Ang 2 | L27: =VLOOKUP(L21,'IURAN TANAH'!$A$2:$S$145,8,FALSE) -> #N/A
B28: Ang 3 | D28: =VLOOKUP(D21,'IURAN TANAH'!$A$2:$S$145,9,FALSE) -> #N/A | F28: Ang 3 | H28: =VLOOKUP(H21,'IURAN TANAH'!$A$2:$S$145,9,FALSE) -> #N/A | J28: Ang 3 | L28: =VLOOKUP(L21,'IURAN TANAH'!$A$2:$S$145,9,FALSE) -> #N/A
B29: Ang 4 | D29: =VLOOKUP(D21,'IURAN TANAH'!$A$2:$S$145,10,FALSE) -> #N/A | F29: Ang 4 | H29: =VLOOKUP(H21,'IURAN TANAH'!$A$2:$S$145,10,FALSE) -> #N/A | J29: Ang 4 | L29: =VLOOKUP(L21,'IURAN TANAH'!$A$2:$S$145,10,FALSE) -> #N/A
B30: Ang 5 | D30: =VLOOKUP(D21,'IURAN TANAH'!$A$2:$S$145,11,FALSE) -> #N/A | F30: Ang 5 | H30: =VLOOKUP(H21,'IURAN TANAH'!$A$2:$S$145,11,FALSE) -> #N/A | J30: Ang 5 | L30: =VLOOKUP(L21,'IURAN TANAH'!$A$2:$S$145,11,FALSE) -> #N/A
B31: Ang 6 | D31: =VLOOKUP(D21,'IURAN TANAH'!$A$2:$S$145,12,FALSE) -> #N/A | F31: Ang 6 | H31: =VLOOKUP(H21,'IURAN TANAH'!$A$2:$S$145,12,FALSE) -> #N/A | J31: Ang 6 | L31: =VLOOKUP(L21,'IURAN TANAH'!$A$2:$S$145,12,FALSE) -> #N/A
B32: Ang 7 | D32: =VLOOKUP(D21,'IURAN TANAH'!$A$2:$S$145,13,FALSE) -> #N/A | F32: Ang 7 | H32: =VLOOKUP(H21,'IURAN TANAH'!$A$2:$S$145,13,FALSE) -> #N/A | J32: Ang 7 | L32: =VLOOKUP(L21,'IURAN TANAH'!$A$2:$S$145,13,FALSE) -> #N/A
B33: Ang 8 | D33: =VLOOKUP(D21,'IURAN TANAH'!$A$2:$S$145,14,FALSE) -> #N/A | F33: Ang 8 | H33: =VLOOKUP(H21,'IURAN TANAH'!$A$2:$S$145,14,FALSE) -> #N/A | J33: Ang 8 | L33: =VLOOKUP(L21,'IURAN TANAH'!$A$2:$S$145,14,FALSE) -> #N/A
B34: Ang 9 | D34: =VLOOKUP(D21,'IURAN TANAH'!$A$2:$S$145,15,FALSE) -> #N/A | F34: Ang 9 | H34: =VLOOKUP(H21,'IURAN TANAH'!$A$2:$S$145,15,FALSE) -> #N/A | J34: Ang 9 | L34: =VLOOKUP(L21,'IURAN TANAH'!$A$2:$S$145,15,FALSE) -> #N/A
B35: Ang 10 | D35: =VLOOKUP(D21,'IURAN TANAH'!$A$2:$S$145,16,FALSE) -> #N/A | F35: Ang 10 | H35: =VLOOKUP(H21,'IURAN TANAH'!$A$2:$S$145,16,FALSE) -> #N/A | J35: Ang 10 | L35: =VLOOKUP(L21,'IURAN TANAH'!$A$2:$S$145,16,FALSE) -> #N/A
B36: Total | D36: =SUM(D26:D35) -> #N/A | F36: Total | H36: =SUM(H26:H35) -> #N/A | J36: Total | L36: =SUM(L26:L35) -> #N/A
B39: No | C39: : | D39: 7 | F39: No | G39: : | H39: 8 | J39: No | K39: : | L39: 9
B40: Nama | C40: : | D40: =VLOOKUP(D39,'IURAN TANAH'!$A$2:$S$145,2,FALSE) -> #N/A | F40: Nama | G40: : | H40: =VLOOKUP(H39,'IURAN TANAH'!$A$2:$S$145,2,FALSE) -> #N/A | J40: Nama | K40: : | L40: =VLOOKUP(L39,'IURAN TANAH'!$A$2:$S$145,2,FALSE) -> #N/A
B41: Alamat | C41: : | D41: =VLOOKUP(D39,'IURAN TANAH'!$A$2:$S$145,3,FALSE) &" " &VLOOKUP(D39,'IURAN TANAH'!$A$2:$S$145,4,FALSE) -> #N/A | F41: Alamat | G41: : | H41: =VLOOKUP(H39,'IURAN TANAH'!$A$2:$S$145,3,FALSE) &" " &VLOOKUP(H39,'IURAN TANAH'!$A$2:$S$145,4,FALSE) -> #N/A | J41: Alamat | K41: : | L41: =VLOOKUP(L39,'IURAN TANAH'!$A$2:$S$145,3,FALSE) &" " &VLOOKUP(L39,'IURAN TANAH'!$A$2:$S$145,4,FALSE) -> #N/A
B43: IURAN : | F43: IURAN : | J43: IURAN :
B44: Ang 1 | D44: =VLOOKUP(D39,'IURAN TANAH'!$A$2:$S$145,7,FALSE) -> #N/A | F44: Ang 1 | H44: =VLOOKUP(H39,'IURAN TANAH'!$A$2:$S$145,7,FALSE) -> #N/A | J44: Ang 1 | L44: =VLOOKUP(L39,'IURAN TANAH'!$A$2:$S$145,7,FALSE) -> #N/A
B45: Ang 2 | D45: =VLOOKUP(D39,'IURAN TANAH'!$A$2:$S$145,8,FALSE) -> #N/A | F45: Ang 2 | H45: =VLOOKUP(H39,'IURAN TANAH'!$A$2:$S$145,8,FALSE) -> #N/A | J45: Ang 2 | L45: =VLOOKUP(L39,'IURAN TANAH'!$A$2:$S$145,8,FALSE) -> #N/A
B46: Ang 3 | D46: =VLOOKUP(D39,'IURAN TANAH'!$A$2:$S$145,9,FALSE) -> #N/A | F46: Ang 3 | H46: =VLOOKUP(H39,'IURAN TANAH'!$A$2:$S$145,9,FALSE) -> #N/A | J46: Ang 3 | L46: =VLOOKUP(L39,'IURAN TANAH'!$A$2:$S$145,9,FALSE) -> #N/A
B47: Ang 4 | D47: =VLOOKUP(D39,'IURAN TANAH'!$A$2:$S$145,10,FALSE) -> #N/A | F47: Ang 4 | H47: =VLOOKUP(H39,'IURAN TANAH'!$A$2:$S$145,10,FALSE) -> #N/A | J47: Ang 4 | L47: =VLOOKUP(L39,'IURAN TANAH'!$A$2:$S$145,10,FALSE) -> #N/A
B48: Ang 5 | D48: =VLOOKUP(D39,'IURAN TANAH'!$A$2:$S$145,11,FALSE) -> #N/A | F48: Ang 5 | H48: =VLOOKUP(H39,'IURAN TANAH'!$A$2:$S$145,11,FALSE) -> #N/A | J48: Ang 5 | L48: =VLOOKUP(L39,'IURAN TANAH'!$A$2:$S$145,11,FALSE) -> #N/A
...

Sheet IURAN BULANAN(2024)
A1: Tabel Iuran Bulanan 2024
A2: BSKM RT 007 | C2: Total Dana : | F2: =SUM(F5:F179) -> 2690000 | G2: =SUM(G5:G179) -> 860000 | H2: =SUM(H5:H179) -> 890000 | I2: =SUM(I5:I179) -> 940000
A4: No | B4: Nama | C4: Perum | D4: Blok | E4: No HP | F4: Total | G4: OKT 2024 | H4: NOV 2024 | I4: DES '2024
A5: 1 | B5: SURYO WINOTO | C5: BRI | D5: A-00 | E5: 085278032476 | F5: =SUM(G5:I5) -> 30000 | G5: 10000 | H5: 10000 | I5: 10000 | R5: Saldo : | S5: 2550000
A6: 2 | B6: RIO | C6: BRI | D6: A-02 | F6: =SUM(G6:I6) -> 30000 | G6: 10000 | H6: 10000 | I6: 10000 | R6: Current | S6: =F2 -> 2690000
A7: 3 | B7: ALEX | C7: BRI | D7: A-03 | E7: 081225141604 | F7: =SUM(G7:I7) -> 0 | S7: =S6-S5 -> 140000
A8: 4 | B8: ANTONI | C8: BRI | D8: A-04 | F8: =SUM(G8:I8) -> 0
A9: 5 | B9: NANANG | C9: BRI | D9: A-06 | F9: =SUM(G9:I9) -> 0
A10: 6 | B10: MARVIN | C10: BRI | D10: A-09 | E10: 082389129277 | F10: =SUM(G10:I10) -> 30000 | G10: 10000 | H10: 10000 | I10: 10000
A11: 7 | B11: PUTRA | C11: BRI | D11: A-14 | E11: 081277134843 | F11: =SUM(G11:I11) -> 0
A12: 8 | B12: ZULFAJRI | C12: BRI | D12: A-16 | E12: 082170182359 | F12: =SUM(G12:I12) -> 0
A13: 9 | B13: SYAFRUDDIN | C13: BRI | D13: A-18 | F13: =SUM(G13:I13) -> 30000 | G13: 10000 | H13: 10000 | I13: 10000
A14: 10 | B14: DAVI | C14: BRI | D14: A-19 | F14: =SUM(G14:I14) -> 30000 | G14: 10000 | H14: 10000 | I14: 10000
A15: 11 | B15: SETIAWAN | C15: BRI | D15: A-20 | E15: 085171602571 | F15: =SUM(G15:I15) -> 20000 | G15: 10000 | H15: 10000
A16: 12 | B16: AHMAT | C16: BRI | D16: A-21 | E16: 081383748814 | F16: =SUM(G16:I16) -> 20000 | H16: 10000 | I16: 10000
A17: 13 | B17: DEFRIZAL | C17: BRI | D17: A-23 | E17: 081388685011 | F17: =SUM(G17:I17) -> 20000 | H17: 10000 | I17: 10000
A18: 14 | B18: ADEK | C18: BRI | D18: A-24 | E18: 082283513560 | F18: =SUM(G18:I18) -> 30000 | G18: 10000 | H18: 10000 | I18: 10000
A19: 15 | B19: AZIZ | C19: BRI | D19: A-07 | E19: 085272036042 | F19: =SUM(G19:I19) -> 30000 | G19: 10000 | H19: 10000 | I19: 10000
A20: 16 | B20: BUSMAN | C20: BRI | D20: B-01 | F20: =SUM(G20:I20) -> 30000 | G20: 10000 | H20: 10000 | I20: 10000
A21: 17 | B21: OYON | C21: BRI | D21: B-02 | F21: =SUM(G21:I21) -> 30000 | G21: 10000 | H21: 10000 | I21: 10000
A22: 18 | B22: RINALDI | C22: BRI | D22: B-03 | F22: =SUM(G22:I22) -> 0
A23: 19 | B23: ABD MUHAFIZ NASUTION | C23: BRI | D23: B-05 | E23: 081270071124 | F23: =SUM(G23:I23) -> 30000 | G23: 10000 | H23: 10000 | I23: 10000
A24: 20 | B24: MAISYARAH | C24: BRI | D24: B-06 | E24: 081261542824 | F24: =SUM(G24:I24) -> 0
A25: 21 | B25: Wili | C25: BRI | D25: B-08 | E25: 082358845454 | F25: =SUM(G25:I25) -> 20000 | G25: 10000 | H25: 10000
A26: 22 | B26: HENDRA | C26: BRI | D26: B-09 | E26: 081378207690 | F26: =SUM(G26:I26) -> 30000 | G26: 10000 | H26: 10000 | I26: 10000
A27: 23 | B27: AZWIR | C27: BRI | D27: B-10 | E27: 081364881722 | F27: =SUM(G27:I27) -> 20000 | G27: 10000 | H27: 10000
A28: 24 | B28: ACIN | C28: BRI | D28: B-11 | E28: 081269541212 | F28: =SUM(G28:I28) -> 30000 | G28: 10000 | H28: 10000 | I28: 10000
A29: 25 | B29: NAZRI | C29: BRI | D29: B-12 | E29: 082286622199 | F29: =SUM(G29:I29) -> 30000 | G29: 10000 | H29: 10000 | I29: 10000
A30: 26 | B30: DANI | C30: BRI | D30: B-14 | E30: 08526328333 | F30: =SUM(G30:I30) -> 20000 | G30: 10000 | H30: 10000
A31: 27 | B31: INDRA /Wahidar | C31: BRI | E31: 082272464633 | F31: =SUM(G31:I31) -> 20000 | H31: 10000 | I31: 10000
A32: 28 | B32: AMRIL HAMBIYA | C32: ERCE | D32: A-01 | F32: =SUM(G32:I32) -> 30000 | G32: 10000 | H32: 10000 | I32: 10000
A33: 29 | B33: SELLY | C33: ERCE | D33: A-02 | F33: =SUM(G33:I33) -> 20000 | G33: 10000 | H33: 10000
A34: 30 | B34: ASRIZAL | C34: ERCE | D34: A-03 | E34: 081372731426 | F34: =SUM(G34:I34) -> 0
A35: 31 | B35: PEMBERLIAN TONI | C35: ERCE | D35: A-04 | F35: =SUM(G35:I35) -> 0
A36: 32 | B36: YUSPIONO | C36: ERCE | D36: A-05 | F36: =SUM(G36:I36) -> 30000 | G36: 10000 | H36: 10000 | I36: 10000
A37: 33 | B37: Risda / Torang S | C37: ERCE | D37: A-06 | F37: =SUM(G37:I37) -> 0
A38: 34 | B38: Heldawati | C38: ERCE | D38: B-01 | E38: 082390914999 | F38: =SUM(G38:I38) -> 30000 | G38: 10000 | H38: 10000 | I38: 10000
A39: 35 | B39: JOKO | C39: ERCE | D39: B-02 | E39: 082384966600 | F39: =SUM(G39:I39) -> 30000 | G39: 10000 | H39: 10000 | I39: 10000
A40: 36 | B40: RUDI | C40: ERCE | D40: B-03 | F40: =SUM(G40:I40) -> 30000 | G40: 10000 | H40: 10000 | I40: 10000
A41: 37 | B41: SILABAN | C41: ERCE | D41: B-05 | E41: 082387631737 | F41: =SUM(G41:I41) -> 20000 | G41: 10000 | I41: 10000
...

Sheet IuranPangkal
G2: Iuran Pangkal Ke
A3: No | B3: NoAnggota | C3: NamaAnggota | D3: Perumahan | E3: No Rumah | F3: Total | G3: Jumlah | H3: tgl | I3: Jumlah | J3: tgl | K3: Jumlah | L3: tgl | M3: Jumlah | N3: tgl | O3: Jumlah | P3: tgl | Q3: Jumlah | R3: tgl | S3: Jumlah | T3: tgl | U3: Jumlah | V3: tgl | W3: Jumlah | X3: tgl | Y3: Jumlah | Z3: tgl | AA3: Jumlah | AB3: tgl | AC3: Jumlah | AD3: tgl
A4: 1 | B4: BSKM-01 | C4: Rio Donal | D4: BRI | E4: A-02 | F4: =G4+I4+K4+M4+O4+Q4+S4+U4+W4+Y4+AA4+AC4 -> 50000 | G4: 50000
A5: 2 | B5: BSKM-02 | C5: Alek | D5: BRI | E5: A-03 | F5: =G5+I5+K5+M5+O5+Q5+S5+U5+W5+Y5+AA5+AC5 -> 50000 | G5: 50000
A6: 3 | B6: BSKM-03 | C6: Antoni | D6: BRI | E6: A-04 | F6: =G6+I6+K6+M6+O6+Q6+S6+U6+W6+Y6+AA6+AC6 -> 50000 | G6: 50000
A7: 4 | B7: BSKM-04 | C7: Nanang S | D7: BRI | E7: A-06 | F7: =G7+I7+K7+M7+O7+Q7+S7+U7+W7+Y7+AA7+AC7 -> 50000 | G7: 50000
A8: 5 | B8: BSKM-05 | C8: Marvin S | D8: BRI | E8: A-09 | F8: =G8+I8+K8+M8+O8+Q8+S8+U8+W8+Y8+AA8+AC8 -> 50000 | G8: 50000
A9: 6 | B9: BSKM-06 | C9: Putra | D9: BRI | E9: A-14 | F9: =G9+I9+K9+M9+O9+Q9+S9+U9+W9+Y9+AA9+AC9 -> 50000 | G9: 50000
A10: 7 | B10: BSKM-07 | C10: Dedek S | D10: BRI | E10: A-15 | F10: =G10+I10+K10+M10+O10+Q10+S10+U10+W10+Y10+AA10+AC10 -> 50000 | G10: 50000
A11: 8 | B11: BSKM-08 | C11: Syafruddin T | D11: BRI | E11: A-18 | F11: =G11+I11+K11+M11+O11+Q11+S11+U11+W11+Y11+AA11+AC11 -> 50000 | G11: 50000
A12: 9 | B12: BSKM-09 | C12: Setiawan | D12: BRI | E12: A-20 | F12: =G12+I12+K12+M12+O12+Q12+S12+U12+W12+Y12+AA12+AC12 -> 50000 | G12: 50000
A13: 10 | B13: BSKM-10 | C13: Ahmad | D13: BRI | E13: A-21 | F13: =G13+I13+K13+M13+O13+Q13+S13+U13+W13+Y13+AA13+AC13 -> 50000 | G13: 50000
A14: 11 | B14: BSKM-11 | C14: Defrizal | D14: BRI | E14: A-23 | F14: =G14+I14+K14+M14+O14+Q14+S14+U14+W14+Y14+AA14+AC14 -> 50000 | G14: 50000
A15: 12 | B15: BSKM-12 | C15: Busman | D15: BRI | E15: B-01 | F15: =G15+I15+K15+M15+O15+Q15+S15+U15+W15+Y15+AA15+AC15 -> 0
A16: 13 | B16: BSKM-13 | C16: Oyon P | D16: BRI | E16: B-02 | F16: =G16+I16+K16+M16+O16+Q16+S16+U16+W16+Y16+AA16+AC16 -> 50000 | G16: 50000
A17: 14 | B17: BSKM-14 | C17: Abd Muhaffis | D17: BRI | E17: B-05 | F17: =G17+I17+K17+M17+O17+Q17+S17+U17+W17+Y17+AA17+AC17 -> 50000 | G17: 50000
A18: 15 | B18: BSKM-15 | C18: Willy | D18: BRI | E18: B-08 | F18: =G18+I18+K18+M18+O18+Q18+S18+U18+W18+Y18+AA18+AC18 -> 50000 | G18: 50000
A19: 16 | B19: BSKM-16 | C19: Hendra F | D19: BRI | E19: B-09 | F19: =G19+I19+K19+M19+O19+Q19+S19+U19+W19+Y19+AA19+AC19 -> 50000 | G19: 50000
A20: 17 | B20: BSKM-17 | C20: Azwir T | D20: BRI | E20: B-10 | F20: =G20+I20+K20+M20+O20+Q20+S20+U20+W20+Y20+AA20+AC20 -> 50000 | G20: 50000
A21: 18 | B21: BSKM-18 | C21: Zul Amri | D21: BRI | E21: B-11 | F21: =G21+I21+K21+M21+O21+Q21+S21+U21+W21+Y21+AA21+AC21 -> 50000 | G21: 50000
A22: 19 | B22: BSKM-19 | C22: Nazri P | D22: BRI | E22: B-12 | F22: =G22+I22+K22+M22+O22+Q22+S22+U22+W22+Y22+AA22+AC22 -> 50000 | G22: 50000
A23: 20 | B23: BSKM-20 | C23: Junaidi | D23: BRI | E23: B-13 | F23: =G23+I23+K23+M23+O23+Q23+S23+U23+W23+Y23+AA23+AC23 -> 50000 | G23: 50000
A24: 21 | B24: BSKM-21 | C24: Dani | D24: BRI | E24: B-14 | F24: =G24+I24+K24+M24+O24+Q24+S24+U24+W24+Y24+AA24+AC24 -> 50000 | G24: 50000
A25: 22 | B25: BSKM-22 | C25: Julio prasetya | D25: GGL | E25: A-15 | F25: =G25+I25+K25+M25+O25+Q25+S25+U25+W25+Y25+AA25+AC25 -> 50000 | G25: 50000
A26: 23 | B26: BSKM-23 | C26: Rohman | D26: GGL | E26: B-03 | F26: =G26+I26+K26+M26+O26+Q26+S26+U26+W26+Y26+AA26+AC26 -> 50000 | G26: 50000
A27: 24 | B27: BSKM-24 | C27: Ikhwan | D27: GGL | E27: B-04 | F27: =G27+I27+K27+M27+O27+Q27+S27+U27+W27+Y27+AA27+AC27 -> 50000 | G27: 50000
... A44: 41 | B44: BSKM-41 | C44: Nanang | D44: RCM | E44: C- | F44: =G44+I44+K44+M44+O44+Q44+S44+U44+W44+Y44+AA44+AC44 -> 50000 | G44: 50000
A45: 42 | B45: BSKM-42 | C45: Edwar | D45: RCM | E45: C-08 | F45: =G45+I45+K45+M45+O45+Q45+S45+U45+W45+Y45+AA45+AC45 -> 0
A46: 43 | B46: BSKM-43 | C46: Zulhadi Aziz | D46: RCM | E46: C-09 | F46: =G46+I46+K46+M46+O46+Q46+S46+U46+W46+Y46+AA46+AC46 -> 50000 | G46: 50000
A47: 44 | B47: BSKM-44 | C47: Amel | D47: RCM | E47: C-11 | F47: =G47+I47+K47+M47+O47+Q47+S47+U47+W47+Y47+AA47+AC47 -> 50000 | G47: 50000
A48: 45 | B48: BSKM-45 | C48: Maidafri | D48: RCM | E48: D-01 | F48: =G48+I48+K48+M48+O48+Q48+S48+U48+W48+Y48+AA48+AC48 -> 50000 | G48: 50000
A49: 46 | B49: BSKM-46 | C49: Suryo W | D49: RCM | E49: K-01 | F49: =G49+I49+K49+M49+O49+Q49+S49+U49+W49+Y49+AA49+AC49 -> 50000 | G49: 50000
A50: 47 | B50: BSKM-47 | C50: Baharuddin | D50: RCM | E50: K-02 | F50: =G50+I50+K50+M50+O50+Q50+S50+U50+W50+Y50+AA50+AC50 -> 50000 | G50: 50000
A51: 48 | B51: BSKM-48 | C51: Yusnel | D51: RCM | E51: K-03 | F51: =G51+I51+K51+M51+O51+Q51+S51+U51+W51+Y51+AA51+AC51 -> 50000 | G51: 50000
A52: 49 | B52: BSKM-49 | C52: Andri Sutan | D52: RCM | E52: K-04 | F52: =G52+I52+K52+M52+O52+Q52+S52+U52+W52+Y52+AA52+AC52 -> 50000 | G52: 50000
A53: 50 | B53: BSKM-50 | C53: Wahyudi | D53: RCM | E53: P-01 | F53: =G53+I53+K53+M53+O53+Q53+S53+U53+W53+Y53+AA53+AC53 -> 50000 | G53: 50000
A54: 51 | B54: BSKM-51 | C54: Muslim | D54: RTA | E54: B-09 | F54: =G54+I54+K54+M54+O54+Q54+S54+U54+W54+Y54+AA54+AC54 -> 50000 | G54: 50000
A55: 52 | B55: BSKM-52 | C55: T Junaidi | D55: RTA | E55: B-10 | F55: =G55+I55+K55+M55+O55+Q55+S55+U55+W55+Y55+AA55+AC55 -> 50000 | G55: 50000
A56: 53 | B56: BSKM-53 | C56: M Andri | D56: RTA | E56: B-12 | F56: =G56+I56+K56+M56+O56+Q56+S56+U56+W56+Y56+AA56+AC56 -> 50000 | G56: 50000
A57: 54 | B57: BSKM-54 | C57: Adi Zulfianto | D57: RTA | E57: C-01 | F57: =G57+I57+K57+M57+O57+Q57+S57+U57+W57+Y57+AA57+AC57 -> 50000 | G57: 50000
...

Sheet Sheet1
